Workbook

Sheet process
A2: Project Location:
A6: Project Complexity: | C6: Low | D6: Medium | E6: High | G6: used to determine estimated P&G
A10: Category | B10: Supplier | J10: Trades Contractors | M10: Add
A11: Bricks | B11: Supplier | G11: Supply Rate | J11: Installation Rate | M11: Supply & Install Best Rate
C12: Picture | D12: Description | E12: unit | F12: no | G12: AA Bricks | H12: Corobrik | I12: Just brick | J12: Con A | K12: Con B | L12: Con C
D14: Clay stock brick - 220x110x85mm | E14: 1 | F14: =E14*55 -> 55 | G14: =F14*1.2 -> 66 | H14: =F14*1.4 -> 77 | O14: Get quote or request call back
A18: Supply & install only
A19: Buyout
A23: Search by
B24: Category
B25: Supplier

Sheet Sheet2
A1: Live pricing
B2: Connecting
B3: Suppliers
B4: Contractors
B5: Sub-Contractors
A7: ESG (Sustainablity) Rating
B8: Main/Sub-Contractors
C9: EPD's | D9: Governance | E9: Carbon policy | F9: SBT's
A11: Ratings
B12: Sub-Contractors
C13: Experience | D13: Pricing | E13: Capability | F13: Financials | G13: Insurances | H13: Resources | I13: BEE | J13: Location | K13: Current commitments
B16: Main Contractors
A19: Connecting
B20: Tradesman
B21: Contractors
A23: Financing
A24: Mastercard | B24: 60days or day bespoke to contract
A27: Sustainable Packageing

Sheet DIY
A1: DIY | B1: Material Only
A3: Live pricing
B4: Connecting
C5: Suppliers | D5: Contractors
D7: Rate
B8: Description | C8: Quantity input | D8: Tekcent | E8: Dudley | F8: Company X
B10: Rhinoboard | C10: =150 -> 150 | D10: =N22 -> 90.25 | E10: =O22 -> 91.2 | F10: =P22 -> 91.2
K16: Quantity Discount Applicable
K18: Supplier Discount Applicable | N18: 0.05 | O18: 0.04 | P18: 0.01
K20: Supplier | L20: Saint Gobain | M20: Base Rate | N20: Tekcent | O20: Dudley | P20: Company X
K21: Quantity | L21: 100 | M21: 100 | N21: =M21*(100%-$N$18) -> 95 | O21: =M21*(100%-$O$18) -> 96 | P21: =M21*(100%-$O$18) -> 96
L22: 199 | M22: 95 | N22: =M22*(100%-$N$18) -> 90.25 | O22: =M22*(100%-$O$18) -> 91.2 | P22: =M22*(100%-$O$18) -> 91.2
L23: 200 | M23: 90 | N23: =M23*(100%-$N$18) -> 85.5 | O23: =M23*(100%-$O$18) -> 86.4 | P23: =M23*(100%-$O$18) -> 86.4
L24: 299 | M24: 90 | N24: =M24*(100%-$N$18) -> 85.5 | O24: =M24*(100%-$O$18) -> 86.4 | P24: =M24*(100%-$O$18) -> 86.4
L25: 300 | M25: 89 | N25: =M25*(100%-$N$18) -> 84.55 | O25: =M25*(100%-$O$18) -> 85.44 | P25: =M25*(100%-$O$18) -> 85.44
L26: 399 | M26: 85 | N26: =M26*(100%-$N$18) -> 80.75 | O26: =M26*(100%-$O$18) -> 81.6 | P26: =M26*(100%-$O$18) -> 81.6
L27: 400 | M27: 84 | N27: =M27*(100%-$N$18) -> 79.8 | O27: =M27*(100%-$O$18) -> 80.64 | P27: =M27*(100%-$O$18) -> 80.64
L28: 499 | M28: 80 | N28: =M28*(100%-$N$18) -> 76 | O28: =M28*(100%-$O$18) -> 76.8 | P28: =M28*(100%-$O$18) -> 76.8

Sheet Sheet1
A1: Code to tie up to API's other system | E1: Qty sliding Scale Pricing | H1: Show cheapest | J1: Location | L1: If logged in (show names of co) | N1: Tickbox | P1: Tickbox | R1: DIY
B3: Item | C3: Pic | D3: unit | E3: Qty | F3: product factor | G3: no. of units | H3: Rate | I3: Amount | L3: Company A | M3: Company B | R3: Material Rate Only
A4: A101 | B4: One Brick Wall | D4: m2 | E4: 100 | F4: =110 -> 110 | G4: =F4*E4 -> 11000 | H4: 450 | I4: =H4*E4 -> 45000 | J4: Request Quote | L4: 460 | M4: 450 | N4: Wastage 15% | P4: Transport
E5: =G4 -> 11000 | H5: bricks required
J18: P&G | K18: Sliding Scale
B23: Rate
C24: Sub-Contractors | D24: Size of works
C26: Main Contractors
C31: Associated items (Estimate Format) | H31: Price buddy

Sheet Look & Feel - Suby
B2: Username | D2: Password
B5: Esti-Mate | E5: LOGO
B8: What we do & Why | D8: Sustainability | E8: About us | F8: Contact us
B13: Search by
B15: Sub-Contractors | C15: Drop down | E15: Suppliers | F15: Drop down
B17: ↑ | E17: ↑ | P17: Click on Concrete - Only gives concrete products
B19: Tekcent | E19: Saint-Gobain
B21: Derek Logan | E21: Coro-brik
B23: Dudley | E23: Lixil
B25: ↓ | E25: ↓
E29: Supplier Product 2 | G29: Supplier Product 3

Sheet Look & Feel - Main Page
B2: Username | D2: Password
B5: COST AI | E5: LOGO
B8: What we do & Why | D8: Sustainability | E8: About us | F8: Contact us
B14: Trades | C14: Drop down | E14: Sub-Contractors | F14: Drop down
B16: ↑ | C16: Scroll | E16: ↑ | F16: Scroll
B18: Concrete | E18: Tekcent | P18: Click on Concrete - Only gives concrete products
B21: Brickwork | E21: Derek Logan
B24: Ceilings | E24: Dudley
B26: ↓ | C26: Scroll | E26: ↓ | F26: Scroll
B31: Supplier Product 1 | D31: Supplier Product 2 | F31: Supplier Product 3
B37: REEL ADVERTISING

Sheet Supplier List
A1: Trade | B1: Material | C1: Suppliers | H1: use autospec to get suppliers
A2: Masonry | B2: Bricks & Paving | C2: Corobrik | D2: Vibro | E2: AA Bricks | F2: Kaleidorock
B3: Blocks (Non load bearing) | C3: Cemteq | D3: Hebel
B4: Brickforce
B5: Sand
B6: Cement
B7: Stone
B8: Concrete (ready mix) | C8: Afrisam | D8: PPC
B9: Formwork | C9: Formscaff
B10: Rebar | C10: Unica | D10: RNS | E10: fortune steel | F10: pro-roof | G10: sa-rebar
B11: Scaffolding
B12: Structural Steel
B13: Partition Boards | C13: Saint-Gobain | D13: Pelican | E13: Capco | F13: Solidwood
B14: Ceilings | C14: Saint-Gobain | D14: Owa | E14: Knauf
B15: Polycarb Roof
B16: Roof Tiles
B17: Glass & Aluminium | C17: Aluglass
B18: Timber trusses
B19: Doors | C19: Ifuba | D19: The door group
B20: Paint
B21: Carpentry & Joinery | C21: PG Bisson
B22: Tiles | C22: Marble Classic
B23: Carpets | C23: Belgotex | D23: KBAC
B24: Audio Visual | C24: ERZ
B25: ICT
B26: Lifts
B27: Lighting | C27: Regent | D27: Lighting Warehouse
B28: Ironmongery | C28: assa abloy | D28: HLL buchels
B29: Fire sprinklers
B30: Furniture
B31: Solar
B32: Louvers | C32: Alania
B33: Cladding | C33: india company
B34: Piping
B35: Waterproofing
B36: Bolts, chemical anchors
B37: WC | C37: Lecicosa
B38: WHB | C38: Lecicosa
B39: Taps | C39: Lixil
B40: Mirrors
...

Sheet Trades
A1: Trade | C1: Supplier | D1: Contractor | H1: Contractor
A2: Preliminaries | C2: AA Bricks | E2: Rank | F2: Company | G2: Primary Commodity | H2: Contractor | K2: Ownership
A3: Demolitions | C3: Afrisam | E3: 1 | F3: PPC Ltd | G3: Concrete, formwork and reinforcement | K3: Listed
A4: Alterations | C4: Alania | E4: 2 | F4: Afrimat | G4: Concrete, formwork and reinforcement | K4: Listed
A5: Earthworks (provisional) | C5: Aluglass | E5: 3 | F5: AfriSam | G5: Concrete, formwork and reinforcement | K5: Private
A6: Lateral support | C6: assa abloy | E6: 4 | F6: Sephaku Holdings | G6: Concrete, formwork and reinforcement | K6: Listed
A7: Piling | C7: Belgotex | E7: 5 | F7: ISG (Technicrete) | G7: Concrete, formwork and reinforcement | K7: Private
A8: Concrete, formwork and reinforcement | C8: Betafence | E8: 6 | F8: AMSA | G8: Structural steelwork | K8: Listed
A9: Precast concrete | C9: Capco | E9: 7 | F9: Macsteel | G9: Structural steelwork | K9: Private
A10: Masonry | C10: Cemteq | E10: 8 | F10: BSi Steel | G10: Structural steelwork | K10: Private
A11: Waterproofing | C11: Corobrik | E11: 9 | F11: NJR Steel | G11: Structural steelwork | K11: Private
A12: Roof coverings, claddings, etc | C12: Data centre | E12: 10 | F12: Scaw Metals | G12: Metalwork | K12: Private
A13: Carpentry and joinery | C13: ERZ | E13: 11 | F13: Safal (Safintra) | G13: Roof coverings, claddings, etc | K13: Private
A14: Ceilings, partitions and access flooring | C14: Formscaff | E14: 12 | F14: Stewarts & Lloyds | G14: Plumbing and drainage | K14: Private
... A28: Provisional sums | C28: Owa | E28: 26 | F28: Kansai Plascon | G28: Paintwork | K28: Subsidiary
C29: Pelican | E29: 27 | F29: AkzoNobel (Dulux) | G29: Paintwork | K29: Subsidiary
C30: PG Bisson | E30: 28 | F30: Saint-Gobain | G30: Ceilings, partitions and access flooring | K30: Subsidiary
C31: PPC | E31: 29 | F31: Sika SA | G31: Chemicals | K31: Subsidiary
C32: Pro-roof | E32: 30 | F32: BASF | G32: Chemicals | K32: Division
C33: pro-roof | E33: 31 | F33: Corobrik | G33: Masonry | K33: Private
C34: Regent | E34: 32 | F34: Trident Steel | G34: Metalwork | K34: Private
C35: RNS | E35: 33 | F35: PG Group | G35: Metalwork | K35: Private
C36: Safintra | E36: 34 | F36: NPC (Huaxin) | G36: Concrete, formwork and reinforcement | K36: Subsidiary
C37: Saint-Gobain | E37: 35 | F37: Mamba Cement | G37: Concrete, formwork and reinforcement | K37: Private
C38: Saint-Gobain | E38: 36 | F38: Actom | G38: Electrical work | K38: Private
C39: sa-rebar | E39: 37 | F39: Allied Steelrode | G39: Concrete, formwork and reinforcement | K39: Private
C40: Sebenza | E40: 38 | F40: Cemza | G40: Concrete, formwork and reinforcement | K40: Private
... C45: Vibro | E45: 43 | F45: StonCor Africa | G45: Chemicals | K45: Subsidiary
E46: 44 | F46: Swartland | G46: Carpentry and joinery | K46: Private
E47: 45 | F47: Barnes Reinforcing | G47: Concrete, formwork and reinforcement | K47: Private
E48: 46 | F48: Sunridge Group | G48: Plumbing and drainage | K48: Private
E49: 47 | F49: ACDC Dynamics | G49: Electrical work | K49: Private
E50: 48 | F50: Alvern Cables | G50: Electrical work | K50: Private
E51: 49 | F51: MiTek | G51: Carpentry and joinery | K51: Subsidiary
E52: 50 | F52: Clotan Steel | G52: Roof coverings, claddings, etc | K52: Private

Sheet Suppliers
A1: Rank | B1: Supplier | C1: Trade | D1: Ownership | E1: Key Strategic Value
A2: 1 | B2: PPC Ltd | C2: Concrete, formwork and reinforcement | D2: Listed | E2: Geographic spread, supply security.
A3: 2 | B3: Afrimat | C3: Concrete, formwork and reinforcement | D3: Listed | E3: Integrated "Pit-to-Pile" solution (Lafarge assets).
A4: 3 | B4: AfriSam | C4: Concrete, formwork and reinforcement | D4: Private | E4: Urban ready-mix dominance.
A5: 4 | B5: Sephaku Holdings | C5: Concrete, formwork and reinforcement | D5: Listed | E5: Efficient, low-cost challenger.
A6: 5 | B6: ISG (Technicrete) | C6: Concrete, formwork and reinforcement | D6: Private | E6: Municipal/Infrastructure spec specialist.
A7: 6 | B7: AMSA | C7: Structural steelwork | D7: Listed | E7: Sole local producer (Risk & Necessity).
A8: 7 | B8: Macsteel | C8: Structural steelwork | D8: Private | E8: Processing capacity, national footprint.
A9: 8 | B9: BSi Steel | C9: Structural steelwork | D9: Private | E9: Agile, export/roofing focus.
A10: 9 | B10: NJR Steel | C10: Structural steelwork | D10: Private | E10: Retail/Trade hybrid, sundry metalwork.
A11: 10 | B11: Scaw Metals | C11: Metalwork | D11: Private | E11: EAF Mini-Mill, import replacement.
A12: 11 | B12: Safal (Safintra) | C12: Roof coverings, claddings, etc | D12: Private | E12: On-site rolling, industrial roofing leader.
A13: 12 | B13: Stewarts & Lloyds | C13: Plumbing and drainage | D13: Private | E13: Industrial fluid control specialist.
... A51: 50 | B51: Clotan Steel | C51: Roof coverings, claddings, etc | D51: Private | E51: IBR/Corrugated sheeting, mobile mills.

Sheet Estimating Platform
A1: Estimating Platform - Live Pricing
A3: Benefits
A4: Saves Time (live pricing)
A5: Bespoke pricing for required quantity
A6: Bespoke pricing to each purchaser
A7: Supplier exposure
A8: Joins Suppliers to Contractors
A9: Information library for Suppliers
A10: Information library for Contractor
A11: EPD's
A12: Carbon/unit
A13: API's to QS, Architects sotfware
... A25: KPI Measure

Sheet Feasibility
A2: No. of trades/works | B2: No. of suppliers/trade | C2: Total No. of suppliers/installors | D2: Monthly fee/each | E2: Total Monthly Fee
A3: =COUNTA('Supplier List'!B1:B51)*0.5 -> 25 | B3: 2 | C3: =A3*B3 -> 50 | D3: =3500 -> 3500 | E3: =C3*D3 -> 175000
A8: Suppliers to pay for listing
A9: Users are free
A10: API & Ties at additional charge (Costx, Revit, etc)
A11: Advertising on page

Sheet Brickwork
A1: Foundation brickwork of NFX clay bricks (14 MPa nominal compressive strength) in class I mortar in One brick walls | B1: m2
A2: Building Sand | B2: m3 | C2: 0.077 | D2: 518.12 | E2: =C2*D2 -> 39.89524 | G2: Class I
A3: Cement General Purpose 32.5 | B3: bg | C3: 0.4 | D3: 140.56 | E3: =C3*D3 -> 56.224
A4: Clay Stockbricks NFX 222 x 105 x 73mm | B4: th | C4: 0.11 | D4: 7533.32 | E4: =C4*D4 -> 828.6652
A5: Artisan Bricklayer | B5: hour | C5: 1.392 | D5: 69.76 | E5: =C5*D5 -> 97.10592
A6: Labourer | B6: hour | C6: 2.784 | D6: 41.33 | E6: =C6*D6 -> 115.06272
A7: Overheads & Sundries @ 2.5% | E7: =C7*D7 -> 0
A8: Profit @ 10% | E8: =C8*D8 -> 0
A9: Rate | B9: m2 | C9: 1 | E9: =C9*D9 -> 0

Sheet Sub-Contractor
D1: Live Saint Gobain | G1: Live Tekcent | J1: minimum price
J2: 300 | K2: m2/load
E3: 0.05 | J3: =4000 -> 4000 | K3: price/load | M3: 0.1 | O3: 0.075 | R3: 0.05
A4: Tekcent | B4: Unit | C4: Qty | D4: Supply Price | E4: Waste | G4: Installation | J4: Site Delivery | M4: P&G % | O4: Profit | Q4: Total Price | R4: Discount | S4: Total Discouted Price | V4: Production rates | Z4: 0.1
G5: Labour | H5: Consumables | V5: Labour | X5: works | Z5: profit
A7: Preliminaries & Generals
A9: Fushplastered ceiling 1 to 2m high | B9: m² | D9: ='Supplier - Saint Gobain'!J7/'Supplier - Saint Gobain'!O7 -> 125 | E9: =D9*E3 -> 6.25 | G9: =Z9 -> 66 | H9: 20 | J9: =J3/J2 -> 13.333333 | M9: =SUM(D9:L9)*M3 -> 23.058333 | O9: =SUM(D9:N9)*O3 -> 19.023125 | Q9: =SUM(D9:P9) -> 272.66479 | R9: =SUM(G9:Q9)*R3 -> 20.703979 | S9: =SUM(F9:R9) -> 434.78356 | V9: =75*8 -> 600 | W9: /per day | X9: 10 | Y9: =V9/X9 -> 60 | Z9: =Y9*(1+Z4) -> 66
A11: Delivery
M15: OHS
M16: Vetting
M17: Guarantees
M18: Retention
M19: Working hours
M20: Access

Sheet Sub Contractor Labour
B1: Base Rate | C1: Overtime | E1: Allowance
A2: Skilled
A3: Un-skilled

Sheet Supplier - Saint Gobain
A1: Tekcent | I1: 0.05 | J1: 0.1 | K1: 0.1
A4: Description | B4: Size | C4: Unit | D4: Length | E4: Breath | F4: Width | G4: Height | H4: Supply Price | I4: Waste | J4: Discount applicable | K4: Factory Delivery | L4: Total Price | O4: Factor conversion
A6: Board
A7: RhinoBoard® 12.5mm | B7: 1200 x 600 | C7: No. | D7: 1.2 | E7: 0.6 | H7: =100 -> 100 | J7: =(H7+I7)*(100%-J1) -> 90 | K7: =SUM(J7)*K1 -> 9 | L7: =SUM(J7:K7) -> 99 | O7: =D7*E7 -> 0.72 | P7: m2 | Q7: boards/m2
A8: Habito® 12.5mm
A9: RhinoBoard® FireStop® dB 15mm
A10: RhinoBoard® DuraLine 15mm
A11: RhinoBoard® RhinoTough® 12.5 mm
A12: RhinoBoard® 12.5 mm
A14: Tape
A15: screws
A17: Hangers
A18: Tees

Sheet Back End Suby 
A1: Description | B1: unit | C1: Quantity | D1: Rate | E1: Total
A2: 500 x 500mm "Berber Point 920" carpet tiles on floors | B2: m2 | H2: Material
A3: Berber Point 920 carpet tiles 500 x 500mm | B3: m2 | C3: =1 -> 1 | D3: =M8 -> 145.5 | E3: =C3*D3 -> 145.5
A4: Labourer | B4: hour | C4: =L14 -> 0.26666667 | D4: =M14 -> 41.33 | E4: =C4*D4 -> 11.021333 | H4: Description | I4: Unit | J4: Quantity | K4: price | L4: m² factor | M4: m² price
A5: Floor Layer | B5: hour | C5: =L15 -> 0.13333333 | D5: =M15 -> 69.76 | E5: =C5*D5 -> 9.3013333 | H5: Berber Point 920 carpet tiles 500 x 500mm | I5: box | J5: =1+I9 -> 1.05 | K5: ='Back End Supplier'!B5 -> 165 | L5: =Z6 -> 1.4285714 | M5: =K5/L5 -> 115.5 | W5: Item | X5: Tiles/box | Y5: m² | Z5: Factor
A6: Overheads & Sundries @ 2.5% | C6: 0.025 | D6: =SUM(E3:E5) -> 165.82267 | E6: =C6*D6 -> 4.1455667 | H6: Glue | I6: ml | J6: 1 | K6: 50 | L6: =Z7 -> 2.5 | M6: =K6/L6 -> 20 | W6: =0.5*0.5 -> 0.25 | X6: 6 | Y6: =W6*X6 -> 1.5 | Z6: =Y6/J5 -> 1.4285714 | AA6: tiles | AB6: =J5/Y6 -> 0.7
A7: Profit @ 10% | C7: 0.1 | D7: =SUM(E3:E6) -> 169.96823 | E7: =C7*D7 -> 16.996823 | H7: Delivery | I7: item | J7: 1 | K7: =5000/500 -> 10 | L7: =5000/5000 -> 1 | M7: =K7/L7 -> 10 | W7: 200 | X7: 80 | Y7: =W7/X7 -> 2.5 | Z7: =Y7/J6 -> 2.5 | AA7: ml
A8: Rate | B8: m2 | E8: =SUM(E3:E7) -> 186.96506 | M8: =SUM(M5:M7) -> 145.5
H9: Wastage | I9: 0.05
S10: =500/5000 -> 0.1
A11: Decription | B11: unit | D11: Rate/Hour | H11: Labour
A12: Labourer | B12: hour | D12: =41.33 -> 41.33
A13: Floor Layer | B13: hour | D13: 69.76 | H13: Hours/day | I13: Output/day | J13: Productivity/hour | K13: No. | L13: Hours/m² | M13: Rate/Hour
A14: Carpenter | B14: hour | D14: 121.54 | H14: 8 | I14: 60 | J14: =H14/I14 -> 0.13333333 | K14: 2 | L14: =J14*K14 -> 0.26666667 | M14: 41.33 | S14: =200 -> 200 | T14: =1.5 -> 1.5 | U14: =S14/T14 -> 133.33333
A15: Production | B15: m² | H15: =8 -> 8 | I15: 60 | J15: =H15/I15 -> 0.13333333 | K15: 1 | L15: =J15*K15 -> 0.13333333 | M15: 69.76 | S15: 50 | T15: 200 | U15: =S15/T15 -> 0.25
H17: Based on 1 Carpet layer and 2 Labourers with output of 60m2 per day
H21: Plant & Machinery
H23: Hours/day | I23: Output/day | J23: Productivity/hour | K23: No. | L23: Hours/m² | M23: Rate/Hour
H24: Berber Point 920 carpet tiles 500 x 500mm | I24: box | J24: =1+I28 -> 1 | K24: ='Back End Supplier'!B24 -> 0 | L24: =Z25 -> 0 | M24: =K24/L24 -> #DIV/0!
H25: Glue | I25: ml | J25: 1 | K25: 50 | L25: =Z26 -> 0 | M25: =K25/L25 -> #DIV/0!
H28: Consumables
H30: Hours/day | I30: Output/day | J30: Productivity/hour | K30: No. | L30: Hours/m² | M30: Rate/Hour
H31: Berber Point 920 carpet tiles 500 x 500mm | I31: box | J31: =1+I35 -> 1 | K31: ='Back End Supplier'!B31 -> 0 | L31: =Z32 -> 0 | M31: =K31/L31 -> #DIV/0!
H32: Glue | I32: ml | J32: 1 | K32: 50 | L32: =Z33 -> 0 | M32: =K32/L32 -> #DIV/0!
G36: * | H36: Scaffold

Sheet Back End Supplier
A1: Supplier | B1: Belgotex | E1: Price Valid for: | F1: 30 | G1: days
A3: Berber Point 920 carpet tiles 500 x 500mm
A5: Base Rate | B5: =165 -> 165 | C5: box
A7: Supplier Discount Applicable | E7: 0.05 | F7: 0.04 | G7: 0.01
A9: Berber Point 920 carpet tiles 500 x 500mm | B9: Belgotex | C9: Qty | D9: Base Rate | E9: Derek Logan | F9: Company A | G9: Company B
A10: Quantity | B10: 0 | C10: 100 | D10: =B5 -> 165 | E10: =$D10*(100%-$E$7) -> 156.75 | F10: =D10*(100%-$F$7) -> 158.4 | G10: =D10*(100%-$G$7) -> 163.35
B11: 0.01 | C11: 199 | D11: =$B$5*(100%-$B11) -> 163.35 | E11: =$D11*(100%-$E$7) -> 155.1825 | F11: =D11*(100%-$F$7) -> 156.816 | G11: =D11*(100%-$G$7) -> 161.7165
B12: =B11+1% -> 0.02 | C12: 200 | D12: =$B$5*(100%-$B12) -> 161.7 | E12: =$D12*(100%-$E$7) -> 153.615 | F12: =D12*(100%-$F$7) -> 155.232 | G12: =D12*(100%-$G$7) -> 160.083
B13: =B12+1% -> 0.03 | C13: 299 | D13: =$B$5*(100%-$B13) -> 160.05 | E13: =$D13*(100%-$E$7) -> 152.0475 | F13: =D13*(100%-$F$7) -> 153.648 | G13: =D13*(100%-$G$7) -> 158.4495
B14: =B13+1% -> 0.04 | C14: 300 | D14: =$B$5*(100%-$B14) -> 158.4 | E14: =$D14*(100%-$E$7) -> 150.48 | F14: =D14*(100%-$F$7) -> 152.064 | G14: =D14*(100%-$G$7) -> 156.816
B15: =B14+1% -> 0.05 | C15: 399 | D15: =$B$5*(100%-$B15) -> 156.75 | E15: =$D15*(100%-$E$7) -> 148.9125 | F15: =D15*(100%-$F$7) -> 150.48 | G15: =D15*(100%-$G$7) -> 155.1825
B16: =B15+1% -> 0.06 | C16: 400 | D16: =$B$5*(100%-$B16) -> 155.1 | E16: =$D16*(100%-$E$7) -> 147.345 | F16: =D16*(100%-$F$7) -> 148.896 | G16: =D16*(100%-$G$7) -> 153.549
B17: =B16+1% -> 0.07 | C17: 499 | D17: =$B$5*(100%-$B17) -> 153.45 | E17: =$D17*(100%-$E$7) -> 145.7775 | F17: =D17*(100%-$F$7) -> 147.312 | G17: =D17*(100%-$G$7) -> 151.9155

Sheet Sheet3
A1: Quantity | B1: A | C1: B | D1: C | E1: D
A2: 100 | B2: 0.05 | C2: 0.05 | D2: 0.05 | E2: 0.05
A3: 200
A4: 300
A5: 400

Sheet Supplier - KBAC
A1: Dereck Logan | J1: 0.05 | K1: 0.1 | L1: 0.1
A3: Description | B3: Size | C3: Unit | D3: Length | E3: Breath | F3: Width | G3: Height | H3: No. | I3: Supply Price | J3: Waste | K3: Discount applicable | L3: Delivery | M3: Total Price | O3: Factor conversion
A5: Carpets
A6: Interface | B6: 600 x 600 | C6: No. | D6: 0.6 | E6: 0.6 | F6: 0 | G6: 0 | H6: 0 | I6: 300 | J6: =ROUND(I6*$J$1,2) -> 15 | K6: =(I6+J6)*(100%-$K$1) -> 283.5 | L6: =ROUND(SUM(K6)*$L$1,2) -> 28.35 | M6: =ROUND(SUM(K6:L6),2) -> 311.85 | O6: =D6*E6 -> 0.36 | P6: m2
A7: Vanguard | B7: 600 x 600 | C7: No. | D7: 0.6 | E7: 0.6 | F7: 0 | G7: 0 | H7: 0 | I7: 300 | J7: =ROUND(I7*$J$1,2) -> 15 | K7: =(I7+J7)*(100%-$K$1) -> 283.5 | L7: =ROUND(SUM(K7)*$L$1,2) -> 28.35 | M7: =ROUND(SUM(K7:L7),2) -> 311.85 | O7: =D7*E7 -> 0.36 | P7: m2
A8: Sealant | B8: 1 Litre | C8: No. | D8: 0 | E8: 0 | F8: 0 | G8: 0 | H8: 1 | I8: 300 | J8: =ROUND(I8*$J$1,2) -> 15 | K8: =(I8+J8)*(100%-$K$1) -> 283.5 | L8: =ROUND(SUM(K8)*$L$1,2) -> 28.35 | M8: =ROUND(SUM(K8:L8),2) -> 311.85 | O8: =H8/0.36 -> 2.7777778 | P8: m2
A9: Tactile
A10: Skirting
A11: RhinoBoard® 12.5 mm

Sheet Function
A1: Connecting People
A2: Suppliers | B2: Sub-Contractor
A3: Sub-Contractor | B3: Main Contractor
A4: Main Contractor | B4: Client
A5: *Tradesmen | B5: Sub-Contractor
A6: Sub-Contractor | B6: *Insurer
A7: Client | B7: *Insurer
A8: Our Platform | B8: Platforms | C8: Costx | D8: CCS | E8: Stackct | F8: Planswift | G8: Proest
A13: Saving Time | B13: Saves time
A14: Live pricing of suppliers
A15: Live pricing of sub-contractors
A18: Favourable pricing | B18: Saves money
A19: Suppliers provide bespoke pricing
A20: Live pricing of contractors
A23: Finance | B23: financier
A24: 60 day buffer | C24: Quote (Ref number) followed by invoice
A25: Assist contractors
A28: ESG (Sustainablity) Rating
A29: EPD's | B29: kg/unit/m2/m3,etc
A30: Governance
A31: Carbon policy
A32: SBT's
A35: Data warehouse | B35: Data collection
A36: Financials
A37: CIDB
A38: Experience
A39: BEE
A40: Commitments
A41: Workmens compensation
A42: OHS Policy
A43: Insurance
A46: BoQ function
A47: Drag & Drop | B47: `DimX - Ribi2
A48: Pricing into BoQ
A51: assist with VO cost (estimate) | B51: Change management
A52: BoQ input function
A53: BoQ measurement function
A54: Estimate
A57: EPD's
A58: A1-A3 & B1 to ….. | B58: Separate company

Sheet Rates
B1: Board
A2: A1 | B2: RhinoBoard® 12.5mm
A3: A2 | B3: Habito® 12.5mm
A4: A3 | B4: RhinoBoard® FireStop® dB 15mm
A5: A4 | B5: RhinoBoard® DuraLine 15mm
A6: A5 | B6: RhinoBoard® RhinoTough® 12.5 mm
A7: A6 | B7: RhinoBoard® 12.5 mm
A8: A7 | B8: Screws
A9: A8 | B9: Habito® GTX-F High Performance Screws 35mm
A10: A9 | B10: Gyproc Sharp-point Screws 42mm
A11: A10 | B11: Gyproc Sharp-point Screws 25mm
A12: A11 | B12: Studs
A13: A12 | B13: 102 mm Gypframe® UltraSTEEL® Studs
... A28: A27 | B28: Gyproc RhinoLite® RhinoGlide®
